Workbook

Sheet 사용법
A1: 귀살 밸런스 시트 (초안)
A3: 작성 | B3: 2026-10-13 초안. 개발현황.md "능력치 & 계산식" 기준. 모든 수치는 출발점이며 플레이하면서 조정합니다.
A5: 색 규칙
A6: 파란 글자 + 노란 칸 | B6: 직접 고치는 값 (입력값)
A7: 검은 글자 | B7: 계산식 — 고치지 않음 (입력값을 바꾸면 자동으로 다시 계산됨)
A8: 초록 글자 | B8: 다른 시트의 값을 가져오는 칸
A10: 시트 구성
A11: 상수 | B11: BalanceConfig에 들어갈 상수 (상한, 계산식 계수, 기본 능력치). 게임으로 내보내는 시트
A12: 레벨표 | B12: 레벨 1~55: 몬스터 레벨 배율, 플레이어 기본 체력·기력, 경험치 곡선. 게임으로 내보내는 시트
A13: 귀신 | B13: 귀신 종류별 기본 수치 (레벨 1 기준). 게임으로 내보내는 시트
A14: 옵션 | B14: 아이템 옵션: 붙을 수 있는 칸, 아이템 레벨 구간별 수치 범위. 게임으로 내보내는 시트
A15: 지역 | B15: 1~3막 지역 레벨, 귀신 최대 동시 등장 수, 귀문 균열 단계. 게임으로 내보내는 시트
A16: 전투시뮬 | B16: 레벨별 '적 하나 잡는 시간'과 '몇 대 맞으면 죽는지'를 계산하고 그래프로 보여 줌. 설계용 (게임으로 내보내지 않음)
A18: 게임에 반영하는 방법
A19: 1. 이 엑셀에서 값 수정 | B19: 파란 글자 칸만 고칩니다.
A20: 2. CSV로 저장 | B20: 게임으로 내보내는 시트(상수·레벨표·귀신·옵션·지역)를 각각 CSV(UTF-8)로 저장 → Assets/Data/Balance/ 폴더 (예: 상수.csv)
A21: 3. Unity에서 불러오기 | B21: Unity 메뉴 [귀살 → 밸런스 불러오기] 버튼 → CSV를 읽어 BalanceConfig 등 데이터에 자동 반영 (백로그 S6에서 만들 기능)
A22: 4. 플레이로 확인 | B22: 개발자 UI(F1)로 레벨·귀신·아이템을 바꿔 가며 체감 확인 (백로그 S1~S2에서 만들 기능)
A24: 주의 | B24: 게임으로 내보내는 시트는 1행이 머리글, 2행부터 데이터입니다. 행 위에 설명을 넣지 말고, 열 이름(머리글)은 바꾸지 마세요 (불러오기 기능이 열 이름으로 값을 찾음). 설명은 이 시트나 셀 메모에 씁니다.
A25: 주의 | B25: 퍼센트는 0.15 = 15% 처럼 소수로 저장됩니다.

Sheet 상수
A1: 키 | B1: 값 | C1: 단위 | D1: 설명
A2: MonsterLevelGrowth | B2: 1.12 | C2: 배 | D2: 몬스터 체력 레벨 배율 = 이 값 ^ (몬스터 레벨 − 1)
A3: MonsterDamageGrowth | B3: 1.09 | C3: 배 | D3: 몬스터 피해 레벨 배율 = 이 값 ^ (몬스터 레벨 − 1). 체력 성장보다 낮게 두어 후반 생존력 유지
A4: ArmorPerEnemyLevel | B4: 15 | D4: 물리 피해 감소 = 방어력 ÷ (방어력 + 이 값 × 적 레벨 + ArmorFlat)
A5: ArmorFlat | B5: 50 | D5: 위 식의 고정값
A6: ArmorReductionCap | B6: 0.85 | C6: % | D6: 물리 피해 감소 상한
A7: ResistCap | B7: 0.75 | C7: % | D7: 저항 기본 상한
A8: ResistCapMax | B8: 0.8 | C8: % | D8: "최대 저항 +%" 옵션으로 올릴 수 있는 최대 상한
A9: DamageReductionCap | B9: 0.5 | C9: % | D9: 피해 감소 % (모든 피해) 상한
A10: BaseCritChance | B10: 0.05 | C10: % | D10: 기본 치명타 확률
A11: BaseCritDamage | B11: 0.5 | C11: % | D11: 기본 치명타 피해 (+50% = ×1.5)
A12: CritChanceCap | B12: 0.75 | C12: % | D12: 치명타 확률 상한
A13: AttackSpeedCap | B13: 1 | C13: % | D13: 공격 속도 상한 (+100%)
A14: CooldownReductionCap | B14: 0.4 | C14: % | D14: 쿨타임 감소 상한
A15: ResourceCostReductionCap | B15: 0.4 | C15: % | D15: 기력 소모 감소 상한
A16: MoveSpeedCap | B16: 0.5 | C16: % | D16: 이동 속도 상한
A17: LevelGapPenaltyPerLevel | B17: 0.03 | C17: % | D17: 적이 플레이어보다 높을 때 1레벨당 주는 피해 감소
A18: LevelGapPenaltyMax | B18: 0.45 | C18: % | D18: 위 감소의 최대치
A19: BaseHealth | B19: 100 | D19: 플레이어 기본 최대 체력
A20: HealthPerLevel | B20: 10 | D20: 레벨당 최대 체력
A21: BaseResource | B21: 100 | D21: 플레이어 기본 최대 기력
A22: ResourcePerLevel | B22: 2 | D22: 레벨당 최대 기력
A23: ResourceRegen | B23: 5 | C23: /초 | D23: 기력 자연 회복
A24: UnarmedMinDamage | B24: 1 | D24: 맨손 최소 피해
A25: UnarmedMaxDamage | B25: 3 | D25: 맨손 최대 피해
A26: EliteHealthMult | B26: 3 | C26: 배 | D26: 정예 체력 배율
A27: EliteDamageMult | B27: 1.5 | C27: 배 | D27: 정예 피해 배율
A28: EliteLevelBonus | B28: 2 | C28: 레벨 | D28: 정예·이름 있는 정예·금 도깨비 몬스터 레벨 보너스
A29: BossLevelBonus | B29: 3 | C29: 레벨 | D29: 보스·중간 보스 몬스터 레벨 보너스
A30: MagicFindHalfPoint | B30: 250 | D30: 아이템 발견 실제 효과 = MF × 이 값 ÷ (MF + 이 값)
A31: ExpBase | B31: 100 | D31: 다음 레벨 필요 경험치 = ExpBase × 레벨 ^ ExpExponent
A32: ExpExponent | B32: 1.5 | D32: 경험치 곡선 지수
A33: ExpLowLevelGap | B33: 5 | C33: 레벨 | D33: 플레이어보다 이만큼 이상 낮은 귀신은 경험치 크게 감소
A34: ExpLowLevelMult | B34: 0.2 | C34: 배 | D34: 위 경우의 경험치 배율
A35: MaxPlayerLevel | B35: 50 | C35: 레벨 | D35: 최대 플레이어 레벨
A36: RiftAreaLevelBase | B36: 12 | D36: 귀문 균열 지역 레벨 = 이 값 + RiftAreaLevelPerTier × 단계
A37: RiftAreaLevelPerTier | B37: 2 | D37: 위 식의 단계당 증가

Sheet 레벨표
A1: Level | B1: MonsterMult | C1: MonsterDamageMult | D1: PlayerHealth | E1: PlayerResource | F1: ExpToNext | G1: ExpTotal | H1: ArmorFor50pct
A2: 1 | B2: =상수!$B$2^(A2-1) -> 1 | C2: =상수!$B$3^(A2-1) -> 1 | D2: =IF(A2<=상수!$B$35,상수!$B$19+상수!$B$20*A2,"") -> 110 | E2: =IF(A2<=상수!$B$35,상수!$B$21+상수!$B$22*A2,"") -> 102 | F2: =IF(A2<상수!$B$35,ROUND(상수!$B$31*A2^상수!$B$32,0),"") -> 100 | G2: =0 -> 0 | H2: =상수!$B$4*A2+상수!$B$5 -> 65
A3: 2 | B3: =상수!$B$2^(A3-1) -> 1.12 | C3: =상수!$B$3^(A3-1) -> 1.09 | D3: =IF(A3<=상수!$B$35,상수!$B$19+상수!$B$20*A3,"") -> 120 | E3: =IF(A3<=상수!$B$35,상수!$B$21+상수!$B$22*A3,"") -> 104 | F3: =IF(A3<상수!$B$35,ROUND(상수!$B$31*A3^상수!$B$32,0),"") -> 283 | G3: =IF(A3<=상수!$B$35,G2+F2,"") -> 100 | H3: =상수!$B$4*A3+상수!$B$5 -> 80
A4: 3 | B4: =상수!$B$2^(A4-1) -> 1.2544 | C4: =상수!$B$3^(A4-1) -> 1.1881 | D4: =IF(A4<=상수!$B$35,상수!$B$19+상수!$B$20*A4,"") -> 130 | E4: =IF(A4<=상수!$B$35,상수!$B$21+상수!$B$22*A4,"") -> 106 | F4: =IF(A4<상수!$B$35,ROUND(상수!$B$31*A4^상수!$B$32,0),"") -> 520 | G4: =IF(A4<=상수!$B$35,G3+F3,"") -> 383 | H4: =상수!$B$4*A4+상수!$B$5 -> 95
A5: 4 | B5: =상수!$B$2^(A5-1) -> 1.404928 | C5: =상수!$B$3^(A5-1) -> 1.295029 | D5: =IF(A5<=상수!$B$35,상수!$B$19+상수!$B$20*A5,"") -> 140 | E5: =IF(A5<=상수!$B$35,상수!$B$21+상수!$B$22*A5,"") -> 108 | F5: =IF(A5<상수!$B$35,ROUND(상수!$B$31*A5^상수!$B$32,0),"") -> 800 | G5: =IF(A5<=상수!$B$35,G4+F4,"") -> 903 | H5: =상수!$B$4*A5+상수!$B$5 -> 110
A6: 5 | B6: =상수!$B$2^(A6-1) -> 1.5735194 | C6: =상수!$B$3^(A6-1) -> 1.4115816 | D6: =IF(A6<=상수!$B$35,상수!$B$19+상수!$B$20*A6,"") -> 150 | E6: =IF(A6<=상수!$B$35,상수!$B$21+상수!$B$22*A6,"") -> 110 | F6: =IF(A6<상수!$B$35,ROUND(상수!$B$31*A6^상수!$B$32,0),"") -> 1118 | G6: =IF(A6<=상수!$B$35,G5+F5,"") -> 1703 | H6: =상수!$B$4*A6+상수!$B$5 -> 125
A7: 6 | B7: =상수!$B$2^(A7-1) -> 1.7623417 | C7: =상수!$B$3^(A7-1) -> 1.538624 | D7: =IF(A7<=상수!$B$35,상수!$B$19+상수!$B$20*A7,"") -> 160 | E7: =IF(A7<=상수!$B$35,상수!$B$21+상수!$B$22*A7,"") -> 112 | F7: =IF(A7<상수!$B$35,ROUND(상수!$B$31*A7^상수!$B$32,0),"") -> 1470 | G7: =IF(A7<=상수!$B$35,G6+F6,"") -> 2821 | H7: =상수!$B$4*A7+상수!$B$5 -> 140
A8: 7 | B8: =상수!$B$2^(A8-1) -> 1.9738227 | C8: =상수!$B$3^(A8-1) -> 1.6771001 | D8: =IF(A8<=상수!$B$35,상수!$B$19+상수!$B$20*A8,"") -> 170 | E8: =IF(A8<=상수!$B$35,상수!$B$21+상수!$B$22*A8,"") -> 114 | F8: =IF(A8<상수!$B$35,ROUND(상수!$B$31*A8^상수!$B$32,0),"") -> 1852 | G8: =IF(A8<=상수!$B$35,G7+F7,"") -> 4291 | H8: =상수!$B$4*A8+상수!$B$5 -> 155
A9: 8 | B9: =상수!$B$2^(A9-1) -> 2.2106814 | C9: =상수!$B$3^(A9-1) -> 1.8280391 | D9: =IF(A9<=상수!$B$35,상수!$B$19+상수!$B$20*A9,"") -> 180 | E9: =IF(A9<=상수!$B$35,상수!$B$21+상수!$B$22*A9,"") -> 116 | F9: =IF(A9<상수!$B$35,ROUND(상수!$B$31*A9^상수!$B$32,0),"") -> 2263 | G9: =IF(A9<=상수!$B$35,G8+F8,"") -> 6143 | H9: =상수!$B$4*A9+상수!$B$5 -> 170
A10: 9 | B10: =상수!$B$2^(A10-1) -> 2.4759632 | C10: =상수!$B$3^(A10-1) -> 1.9925626 | D10: =IF(A10<=상수!$B$35,상수!$B$19+상수!$B$20*A10,"") -> 190 | E10: =IF(A10<=상수!$B$35,상수!$B$21+상수!$B$22*A10,"") -> 118 | F10: =IF(A10<상수!$B$35,ROUND(상수!$B$31*A10^상수!$B$32,0),"") -> 2700 | G10: =IF(A10<=상수!$B$35,G9+F9,"") -> 8406 | H10: =상수!$B$4*A10+상수!$B$5 -> 185
A11: 10 | B11: =상수!$B$2^(A11-1) -> 2.7730788 | C11: =상수!$B$3^(A11-1) -> 2.1718933 | D11: =IF(A11<=상수!$B$35,상수!$B$19+상수!$B$20*A11,"") -> 200 | E11: =IF(A11<=상수!$B$35,상수!$B$21+상수!$B$22*A11,"") -> 120 | F11: =IF(A11<상수!$B$35,ROUND(상수!$B$31*A11^상수!$B$32,0),"") -> 3162 | G11: =IF(A11<=상수!$B$35,G10+F10,"") -> 11106 | H11: =상수!$B$4*A11+상수!$B$5 -> 200
A12: 11 | B12: =상수!$B$2^(A12-1) -> 3.1058482 | C12: =상수!$B$3^(A12-1) -> 2.3673637 | D12: =IF(A12<=상수!$B$35,상수!$B$19+상수!$B$20*A12,"") -> 210 | E12: =IF(A12<=상수!$B$35,상수!$B$21+상수!$B$22*A12,"") -> 122 | F12: =IF(A12<상수!$B$35,ROUND(상수!$B$31*A12^상수!$B$32,0),"") -> 3648 | G12: =IF(A12<=상수!$B$35,G11+F11,"") -> 14268 | H12: =상수!$B$4*A12+상수!$B$5 -> 215
A13: 12 | B13: =상수!$B$2^(A13-1) -> 3.47855 | C13: =상수!$B$3^(A13-1) -> 2.5804264 | D13: =IF(A13<=상수!$B$35,상수!$B$19+상수!$B$20*A13,"") -> 220 | E13: =IF(A13<=상수!$B$35,상수!$B$21+상수!$B$22*A13,"") -> 124 | F13: =IF(A13<상수!$B$35,ROUND(상수!$B$31*A13^상수!$B$32,0),"") -> 4157 | G13: =IF(A13<=상수!$B$35,G12+F12,"") -> 17916 | H13: =상수!$B$4*A13+상수!$B$5 -> 230
A14: 13 | B14: =상수!$B$2^(A14-1) -> 3.895976 | C14: =상수!$B$3^(A14-1) -> 2.8126648 | D14: =IF(A14<=상수!$B$35,상수!$B$19+상수!$B$20*A14,"") -> 230 | E14: =IF(A14<=상수!$B$35,상수!$B$21+상수!$B$22*A14,"") -> 126 | F14: =IF(A14<상수!$B$35,ROUND(상수!$B$31*A14^상수!$B$32,0),"") -> 4687 | G14: =IF(A14<=상수!$B$35,G13+F13,"") -> 22073 | H14: =상수!$B$4*A14+상수!$B$5 -> 245
... A56: 55 | B56: =상수!$B$2^(A56-1) -> 454.75054 | C56: =상수!$B$3^(A56-1) -> 104.96171 | D56: =IF(A56<=상수!$B$35,상수!$B$19+상수!$B$20*A56,"") | E56: =IF(A56<=상수!$B$35,상수!$B$21+상수!$B$22*A56,"") | F56: =IF(A56<상수!$B$35,ROUND(상수!$B$31*A56^상수!$B$32,0),"") | G56: =IF(A56<=상수!$B$35,G55+F55,"") | H56: =상수!$B$4*A56+상수!$B$5 -> 875

Sheet 귀신
A1: Id | B1: Name | C1: Family | D1: Act | E1: Role | F1: BaseHealth | G1: BaseDamage | H1: AttackInterval | I1: DamageType | J1: Armor | K1: ResFire | L1: ResWater | M1: ResPoison | N1: ResYin | O1: MoveSpeed | P1: BaseExp | Q1: Note
A2: mangja | B2: 망자 | C2: 망자 | D2: 1 | E2: 기본 근접 | F2: 30 | G2: 5 | H2: 1.5 | I2: Physical | J2: 5 | K2: 0 | L2: 0 | M2: 0 | N2: 0.2 | O2: 3.5 | P2: 50 | Q2: 지금 게임의 적(체력 30, 공격력 5, 쿨타임 1.5초, 경험치 50)
A3: mangja_starved | B3: 굶어 죽은 망자 | C3: 망자 | D3: 1 | E3: 빠른 근접 | F3: 24 | G3: 5 | H3: 1.2 | I3: Physical | J3: 3 | K3: 0 | L3: 0 | M3: 0 | N3: 0.2 | O3: 5 | P3: 55
A4: mangja_plague | B4: 역병 망자 | C4: 망자 | D4: 1 | E4: 근접 + 독 장판 | F4: 36 | G4: 5 | H4: 1.5 | I4: Poison | J4: 5 | K4: 0 | L4: 0 | M4: 0.5 | N4: 0.2 | O4: 3.2 | P4: 65 | Q4: 죽으면 독 장판
A5: changgwi | B5: 창귀 | C5: 창귀 | D5: 1 | E5: 빠른 떼거리 | F5: 18 | G5: 4 | H5: 1 | I5: Physical | J5: 2 | K5: 0 | L5: 0 | M5: 0 | N5: 0.3 | O5: 5.5 | P5: 35 | Q5: 발견 시 주변 창귀 호출
A6: dokkaebibul | B6: 도깨비불 | C6: 도깨비불 | D6: 1 | E6: 원거리 | F6: 20 | G6: 6 | H6: 2 | I6: Fire | J6: 0 | K6: 0.5 | L6: -0.25 | M6: 0 | N6: 0 | O6: 4 | P6: 45 | Q6: 거리 유지, 다가가면 도망
A7: dueoksini | B7: 두억시니 | C7: 두억시니 | D7: 1 | E7: 탱커 | F7: 90 | G7: 12 | H7: 2.5 | I7: Physical | J7: 25 | K7: 0 | L7: 0 | M7: 0 | N7: 0 | O7: 2.5 | P7: 120 | Q7: 범위 표시 후 내려찍기
A8: seogin | B8: 석인 | C8: 석인 | D8: 1 | E8: 느리고 단단함 | F8: 120 | G8: 10 | H8: 2.5 | I8: Physical | J8: 40 | K8: 0.2 | L8: 0.2 | M8: 0.5 | N8: 0 | O8: 2 | P8: 140
A9: eodukshini | B9: 어둑시니 | C9: 어둑시니 | D9: 1 | E9: 정예 (커짐) | F9: 80 | G9: 8 | H9: 1.5 | I9: Yin | J9: 10 | K9: 0 | L9: 0 | M9: 0 | N9: 0.5 | O9: 3.5 | P9: 200 | Q9: 살아 있을수록 커지고 강해짐
A10: sangun | B10: 산군 | C10: 산군 | D10: 1 | E10: 1막 보스 | F10: 1500 | G10: 18 | H10: 1.8 | I10: Physical | J10: 30 | K10: 0.2 | L10: 0.2 | M10: 0.2 | N10: 0.2 | O10: 5 | P10: 2000 | Q10: 2페이즈: 창귀를 삼켜 회복

Sheet 옵션
A1: Id | B1: Name | C1: StatType | D1: ModKind | E1: MinItemLevel | F1: T1Min | G1: T1Max | H1: T2Min | I1: T2Max | J1: T3Min | K1: T3Max | L1: MainHand | M1: OffHand | N1: Head | O1: Chest | P1: Hands | Q1: Waist | R1: Feet | S1: Neck | T1: Ring
A2: max_health | B2: 최대 체력 | C2: MaxHealth | D2: Flat | E2: 1 | F2: 5 | G2: 15 | H2: 20 | I2: 40 | J2: 45 | K2: 80 | N2: O | O2: O | Q2: O | R2: O | S2: O
A3: added_damage_pct | B3: 추가 피해 % | C3: AddedDamagePct | D3: AddPct | E3: 1 | F3: 0.03 | G3: 0.06 | H3: 0.07 | I3: 0.12 | J3: 0.13 | K3: 0.2 | L3: O | P3: O | S3: O | T3: O
A4: weapon_damage_pct | B4: 무기 피해 % (이 무기) | C4: LocalWeaponDamagePct | D4: AddPct | E4: 1 | F4: 0.1 | G4: 0.25 | H4: 0.26 | I4: 0.5 | J4: 0.51 | K4: 0.8 | L4: O
A5: skill_damage_pct | B5: 스킬 피해 % | C5: SkillDamagePct | D5: AddPct | E5: 5 | F5: 0.04 | G5: 0.08 | H5: 0.09 | I5: 0.15 | J5: 0.16 | K5: 0.25 | M5: O | S5: O
A6: fire_damage_pct | B6: 화 피해 % | C6: FireDamagePct | D6: AddPct | E6: 5 | F6: 0.05 | G6: 0.1 | H6: 0.11 | I6: 0.2 | J6: 0.21 | K6: 0.3 | M6: O | S6: O
A7: added_fire_damage | B7: 화 피해 추가 | C7: AddedFireDamage | D7: Flat | E7: 5 | F7: 2 | G7: 5 | H7: 6 | I7: 15 | J7: 16 | K7: 35 | L7: O
A8: attack_speed | B8: 공격 속도 | C8: AttackSpeedPct | D8: AddPct | E8: 5 | F8: 0.03 | G8: 0.05 | H8: 0.06 | I8: 0.1 | J8: 0.11 | K8: 0.15 | L8: O | P8: O
A9: crit_chance | B9: 치명타 확률 | C9: CritChance | D9: Flat | E9: 5 | F9: 0.01 | G9: 0.02 | H9: 0.02 | I9: 0.04 | J9: 0.04 | K9: 0.06 | P9: O | S9: O | T9: O
A10: crit_damage | B10: 치명타 피해 | C10: CritDamage | D10: Flat | E10: 5 | F10: 0.05 | G10: 0.1 | H10: 0.11 | I10: 0.2 | J10: 0.21 | K10: 0.35 | L10: O | S10: O | T10: O
A11: armor | B11: 방어력 | C11: Armor | D11: Flat | E11: 1 | F11: 5 | G11: 15 | H11: 20 | I11: 50 | J11: 55 | K11: 120 | N11: O | P11: O | Q11: O | R11: O
A12: armor_pct | B12: 방어력 % (이 갑옷) | C12: LocalArmorPct | D12: AddPct | E12: 1 | F12: 0.1 | G12: 0.25 | H12: 0.26 | I12: 0.5 | J12: 0.51 | K12: 0.8 | O12: O
A13: res_fire | B13: 화 저항 | C13: ResFire | D13: Flat | E13: 1 | F13: 0.05 | G13: 0.1 | H13: 0.1 | I13: 0.2 | J13: 0.2 | K13: 0.3 | N13: O | O13: O | Q13: O | R13: O | S13: O | T13: O
A14: res_water | B14: 수 저항 | C14: ResWater | D14: Flat | E14: 1 | F14: 0.05 | G14: 0.1 | H14: 0.1 | I14: 0.2 | J14: 0.2 | K14: 0.3 | N14: O | O14: O | Q14: O | R14: O | S14: O | T14: O
A15: res_poison | B15: 독 저항 | C15: ResPoison | D15: Flat | E15: 1 | F15: 0.05 | G15: 0.1 | H15: 0.1 | I15: 0.2 | J15: 0.2 | K15: 0.3 | N15: O | O15: O | Q15: O | R15: O | S15: O | T15: O
A16: res_yin | B16: 음 저항 | C16: ResYin | D16: Flat | E16: 1 | F16: 0.05 | G16: 0.1 | H16: 0.1 | I16: 0.2 | J16: 0.2 | K16: 0.3 | N16: O | O16: O | Q16: O | R16: O | S16: O | T16: O
A17: res_all | B17: 모든 저항 | C17: ResAll | D17: Flat | E17: 15 | F17: 0.03 | G17: 0.05 | H17: 0.05 | I17: 0.1 | J17: 0.1 | K17: 0.15 | S17: O
A18: damage_reduction | B18: 피해 감소 % | C18: DamageReductionPct | D18: AddPct | E18: 10 | F18: 0.02 | G18: 0.03 | H18: 0.03 | I18: 0.05 | J18: 0.05 | K18: 0.08 | O18: O
A19: health_regen | B19: 체력 재생 (초당) | C19: HealthRegen | D19: Flat | E19: 1 | F19: 1 | G19: 2 | H19: 3 | I19: 6 | J19: 7 | K19: 12 | O19: O
A20: life_on_kill | B20: 처치 시 체력 회복 | C20: LifeOnKill | D20: Flat | E20: 1 | F20: 2 | G20: 5 | H20: 6 | I20: 12 | J20: 13 | K20: 25 | L20: O
A21: max_resource | B21: 최대 기력 | C21: MaxResource | D21: Flat | E21: 1 | F21: 5 | G21: 10 | H21: 11 | I21: 20 | J21: 21 | K21: 30 | N21: O | S21: O
A22: resource_regen | B22: 기력 회복 (초당) | C22: ResourceRegen | D22: Flat | E22: 5 | F22: 0.5 | G22: 1 | H22: 1 | I22: 2 | J22: 2 | K22: 3 | S22: O | T22: O
A23: resource_cost | B23: 기력 소모 감소 | C23: ResourceCostReduction | D23: Flat | E23: 10 | F23: 0.03 | G23: 0.05 | H23: 0.05 | I23: 0.08 | J23: 0.08 | K23: 0.12 | M23: O
A24: cooldown | B24: 쿨타임 감소 | C24: CooldownReduction | D24: Flat | E24: 10 | F24: 0.03 | G24: 0.05 | H24: 0.05 | I24: 0.08 | J24: 0.08 | K24: 0.12 | M24: O | N24: O
A25: move_speed | B25: 이동 속도 | C25: MoveSpeedPct | D25: AddPct | E25: 1 | F25: 0.03 | G25: 0.05 | H25: 0.06 | I25: 0.1 | J25: 0.1 | K25: 0.15 | R25: O
A26: potion_heal | B26: 물약 회복량 % | C26: PotionHealPct | D26: AddPct | E26: 5 | F26: 0.05 | G26: 0.1 | H26: 0.11 | I26: 0.2 | J26: 0.21 | K26: 0.3 | Q26: O
A27: magic_find | B27: 아이템 발견 % | C27: MagicFind | D27: Flat | E27: 5 | F27: 0.05 | G27: 0.1 | H27: 0.11 | I27: 0.2 | J27: 0.21 | K27: 0.35 | T27: O
A28: gold_find | B28: 엽전 획득 % | C28: GoldFind | D28: Flat | E28: 1 | F28: 0.1 | G28: 0.2 | H28: 0.21 | I28: 0.4 | J28: 0.41 | K28: 0.6 | T28: O
A29: all_skills | B29: 모든 스킬 랭크 | C29: AllSkillRank | D29: Flat | E29: 20 | F29: 1 | G29: 1 | H29: 1 | I29: 1 | J29: 1 | K29: 2 | S29: O
A30: max_resist | B30: 최대 저항 +% | C30: MaxResistBonus | D30: Flat | E30: 30 | F30: 0 | G30: 0 | H30: 0.01 | I30: 0.02 | J30: 0.02 | K30: 0.05 | O30: O

Sheet 지역
A1: Id | B1: Act | C1: No | D1: Name | E1: Type | F1: Tileset | G1: AreaLevel | H1: MaxEnemies | I1: Note
A2: ruined_mountain | B2: 1 | C2: 1 | D2: 무너진 본산 | E2: Handmade | F2: 폐사찰 | G2: 1 | H2: 6 | I2: 프롤로그
A3: stairs108 | B3: 1 | C3: 2 | D3: 백팔 계단 | E3: Random | F3: 폐사찰 | G3: 2 | H3: 20
A4: misty_path | B4: 1 | C4: 3 | D4: 안개 산길 | E4: Random | F4: 산길·숲 | G4: 3 | H4: 20
A5: village_below | B5: 1 | C5: 4 | D5: 산 아래 마을 | E5: Handmade | G5: 4 | H5: 6 | I5: 탈환 후 거점(안전)
A6: terraced_field | B6: 1 | C6: 5 | D6: 다랑이 논 | E6: Random | F6: 산길·숲 | G6: 5 | H6: 20
A7: shrine_pass | B7: 1 | C7: 6 | D7: 서낭당 고개 | E7: Random | F7: 산길·숲 | G7: 6 | H7: 20 | I7: 웨이포인트
A8: slash_burn_village | B8: 1 | C8: 7 | D8: 버려진 화전민 마을 | E8: Random | F8: 산길·숲 | G8: 7 | H8: 20
A9: old_mine_1 | B9: 1 | C9: 8 | D9: 폐금광 1층 | E9: Random | F9: 동굴 | G9: 8 | H9: 20 | I9: 선택 던전
A10: old_mine_2 | B10: 1 | C10: 9 | D10: 폐금광 2층 | E10: Random | F10: 동굴 | G10: 9 | H10: 20 | I10: 선택 던전
A11: bamboo_forest | B11: 1 | C11: 10 | D11: 대나무 숲 | E11: Random | F11: 산길·숲 | G11: 9 | H11: 20
A12: tomb_hill | B12: 1 | C12: 11 | D12: 고분 언덕 | E12: Random | F12: 고분 | G12: 10 | H12: 20
A13: royal_tomb_1 | B13: 1 | C13: 12 | D13: 옛 왕릉 1층 | E13: Random | F13: 고분 | G13: 11 | H13: 20 | I13: 선택 던전
A14: royal_tomb_2 | B14: 1 | C14: 13 | D14: 옛 왕릉 2층 | E14: Random | F14: 고분 | G14: 12 | H14: 20 | I14: 선택 던전
A15: changgwi_valley | B15: 1 | C15: 14 | D15: 창귀 골짜기 | E15: Random | F15: 산길·숲 | G15: 12 | H15: 20
A16: sangun_den | B16: 1 | C16: 15 | D16: 산군의 굴 | E16: Handmade | F16: 동굴 | G16: 13 | H16: 6 | I16: 보스 산군
A17: river_pass | B17: 2 | C17: 1 | D17: 강으로 가는 고갯길 | E17: Random | F17: 산길·숲 | G17: 14 | H17: 20
A18: hwangpo_ferry | B18: 2 | C18: 2 | D18: 황포 나루 | E18: Handmade | G18: 0 | H18: 0 | I18: 거점(안전)
A19: reed_field | B19: 2 | C19: 3 | D19: 갈대밭 | E19: Random | F19: 강변·갈대밭 | G19: 15 | H19: 20
A20: willow_marsh | B20: 2 | C20: 4 | D20: 버드나무 늪 | E20: Random | F20: 늪 | G20: 16 | H20: 20 | I20: 웨이포인트
A21: watermill_village | B21: 2 | C21: 5 | D21: 멈춘 물레방아 마을 | E21: Random | F21: 강변·갈대밭 | G21: 17 | H21: 20
A22: funeral_pass | B22: 2 | C22: 6 | D22: 상엿소리 고개 | E22: Random | F22: 강변·갈대밭 | G22: 18 | H22: 20
A23: imugi_cave_1 | B23: 2 | C23: 7 | D23: 이무기 굴 1층 | E23: Random | F23: 물 동굴 | G23: 19 | H23: 20 | I23: 선택 던전
A24: imugi_cave_2 | B24: 2 | C24: 8 | D24: 이무기 굴 2층 | E24: Random | F24: 물 동굴 | G24: 20 | H24: 20 | I24: 선택 던전
A25: dragon_falls | B25: 2 | C25: 9 | D25: 용소 폭포 | E25: Random | F25: 강변·갈대밭 | G25: 19 | H25: 20 | I25: 웨이포인트
A26: drowned_village | B26: 2 | C26: 10 | D26: 물에 잠긴 마을 | E26: Random | F26: 늪 | G26: 20 | H26: 20
A27: shaman_shrine_1 | B27: 2 | C27: 11 | D27: 무녀의 신당 지하 1층 | E27: Random | F27: 물 동굴 | G27: 21 | H27: 20 | I27: 선택 던전
A28: shaman_shrine_2 | B28: 2 | C28: 12 | D28: 무녀의 신당 지하 2층 | E28: Random | F28: 물 동굴 | G28: 22 | H28: 20 | I28: 선택 던전
A29: sunken_temple_yard | B29: 2 | C29: 13 | D29: 수몰 사찰 경내 | E29: Random | F29: 수몰 사찰 | G29: 22 | H29: 20
A30: sunken_hall_1 | B30: 2 | C30: 14 | D30: 수몰 사찰 법당 1층 | E30: Random | F30: 수몰 사찰 | G30: 23 | H30: 20
A31: sunken_hall_2 | B31: 2 | C31: 15 | D31: 수몰 사찰 법당 2층 | E31: Random | F31: 수몰 사찰 | G31: 24 | H31: 20
A32: sunken_main_hall | B32: 2 | C32: 16 | D32: 잠긴 대웅전 | E32: Handmade | F32: 수몰 사찰 | G32: 24 | H32: 6 | I32: 보스 타락한 대사형
A33: broken_border_field | B33: 3 | C33: 1 | D33: 경계가 무너진 들판 | E33: Random | F33: 산길·숲 | G33: 25 | H33: 20
A34: iljumun_camp | B34: 3 | C34: 2 | D34: 일주문 야영지 | E34: Handmade | G34: 0 | H34: 0 | I34: 거점(안전)
A35: returned_mountain | B35: 3 | C35: 3 | D35: 다시 찾은 본산 | E35: Random | F35: 폐사찰 | G35: 26 | H35: 20
A36: jumuk_archive | B36: 3 | C36: 4 | D36: 주묵 서고 | E36: Random | F36: 주묵 지하 | G36: 27 | H36: 20 | I36: 웨이포인트
A37: training_cave_1 | B37: 3 | C37: 5 | D37: 갈래 수련동 1층 | E37: Random | F37: 주묵 지하 | G37: 28 | H37: 20 | I37: 선택 던전
A38: training_cave_2 | B38: 3 | C38: 6 | D38: 갈래 수련동 2층 | E38: Random | F38: 주묵 지하 | G38: 29 | H38: 20 | I38: 선택 던전
A39: soul_vault_1 | B39: 3 | C39: 7 | D39: 봉혼고 1층 | E39: Random | F39: 주묵 지하 | G39: 28 | H39: 20
A40: soul_vault_2 | B40: 3 | C40: 8 | D40: 봉혼고 2층 | E40: Random | F40: 주묵 지하 | G40: 29 | H40: 20
...

Sheet 전투시뮬
A1: 전투 시뮬레이션 — 레벨에 맞는 장비를 끼고, 같은 레벨의 기준 귀신(망자)과 싸운다고 가정
A3: 기준 귀신 Id | B3: mangja | C3: 귀신 시트의 Id
A4: 레벨 1 무기 평균 피해 | B4: 6 | C4: 가정: 레벨 1 장비의 무기 피해 (최소~최대 평균)
A5: 무기 피해 레벨당 성장 | B5: 1.115 | C5: 가정: 무기 평균 피해 = 위 값 × 이 값 ^ (레벨 − 1)
A6: 스킬 배율 | B6: 1.2 | C6: 가정: 주력 스킬 배율 (부적 투사체 랭크 1 = 120%)
A7: 초당 공격 횟수 | B7: 1 | C7: 가정: 공격 속도 보너스 포함
A8: 레벨당 추가 피해 % | B8: 0.02 | C8: 가정: 장비로 얻는 추가 피해 % (레벨 × 이 값)
A9: 레벨당 치명타 확률 증가 | B9: 0.003 | C9: 가정: 기본 5% + 레벨 × 이 값
A10: 레벨당 장비 체력 | B10: 4 | C10: 가정: 장비로 얻는 최대 체력 (레벨 × 이 값)
A11: 방어력 = 레벨 × A + B 의 A | B11: 12 | C11: 가정: 레벨에 맞는 장비의 방어력
A12: 방어력 = 레벨 × A + B 의 B | B12: 20
A13: 목표: 일반 귀신 처치 시간 (초) | B13: 2.5 | C13: 그래프에서 비교할 목표선
A14: 목표: 같은 레벨 귀신에게 버티는 타수 | B14: 15 | C14: 그래프에서 비교할 목표선
A15: 기준 귀신 기본 체력 | B15: =INDEX(귀신!$F:$F,MATCH($B$3,귀신!$A:$A,0)) -> 30
A16: 기준 귀신 기본 피해 | B16: =INDEX(귀신!$G:$G,MATCH($B$3,귀신!$A:$A,0)) -> 5
A17: 기준 귀신 공격 간격 (초) | B17: =INDEX(귀신!$H:$H,MATCH($B$3,귀신!$A:$A,0)) -> 1.5
A18: 기준 귀신 방어력 (물리 피해 감소에 미사용, 참고) | B18: =INDEX(귀신!$J:$J,MATCH($B$3,귀신!$A:$A,0)) -> 5
A20: Level | B20: MonsterMult | C20: WeaponAvg | D20: AddedPct | E20: CritChance | F20: CritMult | G20: PlayerDPS | H20: EnemyHealth | I20: TimeToKill(s) | J20: PlayerHealth | K20: Armor | L20: PhysReduction | M20: DamageTaken | N20: HitsToDie | O20: SurviveSec | P20: TTK목표 | Q20: 타수목표
A21: 1 | B21: =INDEX(레벨표!$B:$B,MATCH(A21,레벨표!$A:$A,0)) -> 1 | C21: =$B$4*$B$5^(A21-1) -> 6 | D21: =$B$8*A21 -> 0.02 | E21: =MIN(상수!$B$10+$B$9*A21,상수!$B$12) -> 0.053 | F21: =1+E21*상수!$B$11 -> 1.0265 | G21: =C21*$B$6*(1+D21)*F21*$B$7 -> 7.538616 | H21: =$B$15*B21 -> 30 | I21: =H21/G21 -> 3.9795103 | J21: =INDEX(레벨표!$D:$D,MATCH(A21,레벨표!$A:$A,0))+$B$10*A21 -> 114 | K21: =$B$11*A21+$B$12 -> 32 | L21: =MIN(K21/(K21+상수!$B$4*A21+상수!$B$5),상수!$B$6) -> 0.32989691 | M21: =$B$16*INDEX(레벨표!$C:$C,MATCH(A21,레벨표!$A:$A,0))*(1-L21) -> 3.3505155 | N21: =J21/M21 -> 34.024615 | O21: =N21*$B$17 -> 51.036923 | P21: =$B$13 -> 2.5 | Q21: =$B$14 -> 15
A22: 2 | B22: =INDEX(레벨표!$B:$B,MATCH(A22,레벨표!$A:$A,0)) -> 1.12 | C22: =$B$4*$B$5^(A22-1) -> 6.69 | D22: =$B$8*A22 -> 0.04 | E22: =MIN(상수!$B$10+$B$9*A22,상수!$B$12) -> 0.056 | F22: =1+E22*상수!$B$11 -> 1.028 | G22: =C22*$B$6*(1+D22)*F22*$B$7 -> 8.5828954 | H22: =$B$15*B22 -> 33.6 | I22: =H22/G22 -> 3.9147629 | J22: =INDEX(레벨표!$D:$D,MATCH(A22,레벨표!$A:$A,0))+$B$10*A22 -> 128 | K22: =$B$11*A22+$B$12 -> 44 | L22: =MIN(K22/(K22+상수!$B$4*A22+상수!$B$5),상수!$B$6) -> 0.35483871 | M22: =$B$16*INDEX(레벨표!$C:$C,MATCH(A22,레벨표!$A:$A,0))*(1-L22) -> 3.516129 | N22: =J22/M22 -> 36.40367 | O22: =N22*$B$17 -> 54.605505 | P22: =$B$13 -> 2.5 | Q22: =$B$14 -> 15
A23: 3 | B23: =INDEX(레벨표!$B:$B,MATCH(A23,레벨표!$A:$A,0)) -> 1.2544 | C23: =$B$4*$B$5^(A23-1) -> 7.45935 | D23: =$B$8*A23 -> 0.06 | E23: =MIN(상수!$B$10+$B$9*A23,상수!$B$12) -> 0.059 | F23: =1+E23*상수!$B$11 -> 1.0295 | G23: =C23*$B$6*(1+D23)*F23*$B$7 -> 9.7681978 | H23: =$B$15*B23 -> 37.632 | I23: =H23/G23 -> 3.8525018 | J23: =INDEX(레벨표!$D:$D,MATCH(A23,레벨표!$A:$A,0))+$B$10*A23 -> 142 | K23: =$B$11*A23+$B$12 -> 56 | L23: =MIN(K23/(K23+상수!$B$4*A23+상수!$B$5),상수!$B$6) -> 0.37086093 | M23: =$B$16*INDEX(레벨표!$C:$C,MATCH(A23,레벨표!$A:$A,0))*(1-L23) -> 3.7374007 | N23: =J23/M23 -> 37.994321 | O23: =N23*$B$17 -> 56.991481 | P23: =$B$13 -> 2.5 | Q23: =$B$14 -> 15
A24: 4 | B24: =INDEX(레벨표!$B:$B,MATCH(A24,레벨표!$A:$A,0)) -> 1.404928 | C24: =$B$4*$B$5^(A24-1) -> 8.3171753 | D24: =$B$8*A24 -> 0.08 | E24: =MIN(상수!$B$10+$B$9*A24,상수!$B$12) -> 0.062 | F24: =1+E24*상수!$B$11 -> 1.031 | G24: =C24*$B$6*(1+D24)*F24*$B$7 -> 11.11321 | H24: =$B$15*B24 -> 42.14784 | I24: =H24/G24 -> 3.7925892 | J24: =INDEX(레벨표!$D:$D,MATCH(A24,레벨표!$A:$A,0))+$B$10*A24 -> 156 | K24: =$B$11*A24+$B$12 -> 68 | L24: =MIN(K24/(K24+상수!$B$4*A24+상수!$B$5),상수!$B$6) -> 0.38202247 | M24: =$B$16*INDEX(레벨표!$C:$C,MATCH(A24,레벨표!$A:$A,0))*(1-L24) -> 4.0014941 | N24: =J24/M24 -> 38.985438 | O24: =N24*$B$17 -> 58.478157 | P24: =$B$13 -> 2.5 | Q24: =$B$14 -> 15
A25: 5 | B25: =INDEX(레벨표!$B:$B,MATCH(A25,레벨표!$A:$A,0)) -> 1.5735194 | C25: =$B$4*$B$5^(A25-1) -> 9.2736504 | D25: =$B$8*A25 -> 0.1 | E25: =MIN(상수!$B$10+$B$9*A25,상수!$B$12) -> 0.065 | F25: =1+E25*상수!$B$11 -> 1.0325 | G25: =C25*$B$6*(1+D25)*F25*$B$7 -> 12.639058 | H25: =$B$15*B25 -> 47.205581 | I25: =H25/G25 -> 3.734897 | J25: =INDEX(레벨표!$D:$D,MATCH(A25,레벨표!$A:$A,0))+$B$10*A25 -> 170 | K25: =$B$11*A25+$B$12 -> 80 | L25: =MIN(K25/(K25+상수!$B$4*A25+상수!$B$5),상수!$B$6) -> 0.3902439 | M25: =$B$16*INDEX(레벨표!$C:$C,MATCH(A25,레벨표!$A:$A,0))*(1-L25) -> 4.3036025 | N25: =J25/M25 -> 39.50179 | O25: =N25*$B$17 -> 59.252685 | P25: =$B$13 -> 2.5 | Q25: =$B$14 -> 15
A26: 6 | B26: =INDEX(레벨표!$B:$B,MATCH(A26,레벨표!$A:$A,0)) -> 1.7623417 | C26: =$B$4*$B$5^(A26-1) -> 10.34012 | D26: =$B$8*A26 -> 0.12 | E26: =MIN(상수!$B$10+$B$9*A26,상수!$B$12) -> 0.068 | F26: =1+E26*상수!$B$11 -> 1.034 | G26: =C26*$B$6*(1+D26)*F26*$B$7 -> 14.369624 | H26: =$B$15*B26 -> 52.87025 | I26: =H26/G26 -> 3.6793065 | J26: =INDEX(레벨표!$D:$D,MATCH(A26,레벨표!$A:$A,0))+$B$10*A26 -> 184 | K26: =$B$11*A26+$B$12 -> 92 | L26: =MIN(K26/(K26+상수!$B$4*A26+상수!$B$5),상수!$B$6) -> 0.39655172 | M26: =$B$16*INDEX(레벨표!$C:$C,MATCH(A26,레벨표!$A:$A,0))*(1-L26) -> 4.6423999 | N26: =J26/M26 -> 39.634673 | O26: =N26*$B$17 -> 59.452009 | P26: =$B$13 -> 2.5 | Q26: =$B$14 -> 15
A27: 7 | B27: =INDEX(레벨표!$B:$B,MATCH(A27,레벨표!$A:$A,0)) -> 1.9738227 | C27: =$B$4*$B$5^(A27-1) -> 11.529234 | D27: =$B$8*A27 -> 0.14 | E27: =MIN(상수!$B$10+$B$9*A27,상수!$B$12) -> 0.071 | F27: =1+E27*상수!$B$11 -> 1.0355 | G27: =C27*$B$6*(1+D27)*F27*$B$7 -> 16.331898 | H27: =$B$15*B27 -> 59.214681 | I27: =H27/G27 -> 3.6257073 | J27: =INDEX(레벨표!$D:$D,MATCH(A27,레벨표!$A:$A,0))+$B$10*A27 -> 198 | K27: =$B$11*A27+$B$12 -> 104 | L27: =MIN(K27/(K27+상수!$B$4*A27+상수!$B$5),상수!$B$6) -> 0.4015444 | M27: =$B$16*INDEX(레벨표!$C:$C,MATCH(A27,레벨표!$A:$A,0))*(1-L27) -> 5.0183498 | N27: =J27/M27 -> 39.455201 | O27: =N27*$B$17 -> 59.182802 | P27: =$B$13 -> 2.5 | Q27: =$B$14 -> 15
A28: 8 | B28: =INDEX(레벨표!$B:$B,MATCH(A28,레벨표!$A:$A,0)) -> 2.2106814 | C28: =$B$4*$B$5^(A28-1) -> 12.855096 | D28: =$B$8*A28 -> 0.16 | E28: =MIN(상수!$B$10+$B$9*A28,상수!$B$12) -> 0.074 | F28: =1+E28*상수!$B$11 -> 1.037 | G28: =C28*$B$6*(1+D28)*F28*$B$7 -> 18.556382 | H28: =$B$15*B28 -> 66.320442 | I28: =H28/G28 -> 3.5739963 | J28: =INDEX(레벨표!$D:$D,MATCH(A28,레벨표!$A:$A,0))+$B$10*A28 -> 212 | K28: =$B$11*A28+$B$12 -> 116 | L28: =MIN(K28/(K28+상수!$B$4*A28+상수!$B$5),상수!$B$6) -> 0.40559441 | M28: =$B$16*INDEX(레벨표!$C:$C,MATCH(A28,레벨표!$A:$A,0))*(1-L28) -> 5.4329834 | N28: =J28/M28 -> 39.020918 | O28: =N28*$B$17 -> 58.531377 | P28: =$B$13 -> 2.5 | Q28: =$B$14 -> 15
A29: 9 | B29: =INDEX(레벨표!$B:$B,MATCH(A29,레벨표!$A:$A,0)) -> 2.4759632 | C29: =$B$4*$B$5^(A29-1) -> 14.333432 | D29: =$B$8*A29 -> 0.18 | E29: =MIN(상수!$B$10+$B$9*A29,상수!$B$12) -> 0.077 | F29: =1+E29*상수!$B$11 -> 1.0385 | G29: =C29*$B$6*(1+D29)*F29*$B$7 -> 21.077541 | H29: =$B$15*B29 -> 74.278895 | I29: =H29/G29 -> 3.5240778 | J29: =INDEX(레벨표!$D:$D,MATCH(A29,레벨표!$A:$A,0))+$B$10*A29 -> 226 | K29: =$B$11*A29+$B$12 -> 128 | L29: =MIN(K29/(K29+상수!$B$4*A29+상수!$B$5),상수!$B$6) -> 0.40894569 | M29: =$B$16*INDEX(레벨표!$C:$C,MATCH(A29,레벨표!$A:$A,0))*(1-L29) -> 5.8885637 | N29: =J29/M29 -> 38.379478 | O29: =N29*$B$17 -> 57.569217 | P29: =$B$13 -> 2.5 | Q29: =$B$14 -> 15
A30: 10 | B30: =INDEX(레벨표!$B:$B,MATCH(A30,레벨표!$A:$A,0)) -> 2.7730788 | C30: =$B$4*$B$5^(A30-1) -> 15.981777 | D30: =$B$8*A30 -> 0.2 | E30: =MIN(상수!$B$10+$B$9*A30,상수!$B$12) -> 0.08 | F30: =1+E30*상수!$B$11 -> 1.04 | G30: =C30*$B$6*(1+D30)*F30*$B$7 -> 23.934309 | H30: =$B$15*B30 -> 83.192363 | I30: =H30/G30 -> 3.4758624 | J30: =INDEX(레벨표!$D:$D,MATCH(A30,레벨표!$A:$A,0))+$B$10*A30 -> 240 | K30: =$B$11*A30+$B$12 -> 140 | L30: =MIN(K30/(K30+상수!$B$4*A30+상수!$B$5),상수!$B$6) -> 0.41176471 | M30: =$B$16*INDEX(레벨표!$C:$C,MATCH(A30,레벨표!$A:$A,0))*(1-L30) -> 6.3879214 | N30: =J30/M30 -> 37.570907 | O30: =N30*$B$17 -> 56.35636 | P30: =$B$13 -> 2.5 | Q30: =$B$14 -> 15
A31: 11 | B31: =INDEX(레벨표!$B:$B,MATCH(A31,레벨표!$A:$A,0)) -> 3.1058482 | C31: =$B$4*$B$5^(A31-1) -> 17.819681 | D31: =$B$8*A31 -> 0.22 | E31: =MIN(상수!$B$10+$B$9*A31,상수!$B$12) -> 0.083 | F31: =1+E31*상수!$B$11 -> 1.0415 | G31: =C31*$B$6*(1+D31)*F31*$B$7 -> 27.170665 | H31: =$B$15*B31 -> 93.175446 | I31: =H31/G31 -> 3.4292663 | J31: =INDEX(레벨표!$D:$D,MATCH(A31,레벨표!$A:$A,0))+$B$10*A31 -> 254 | K31: =$B$11*A31+$B$12 -> 152 | L31: =MIN(K31/(K31+상수!$B$4*A31+상수!$B$5),상수!$B$6) -> 0.41416894 | M31: =$B$16*INDEX(레벨표!$C:$C,MATCH(A31,레벨표!$A:$A,0))*(1-L31) -> 6.9343759 | N31: =J31/M31 -> 36.629108 | O31: =N31*$B$17 -> 54.943661 | P31: =$B$13 -> 2.5 | Q31: =$B$14 -> 15
A32: 12 | B32: =INDEX(레벨표!$B:$B,MATCH(A32,레벨표!$A:$A,0)) -> 3.47855 | C32: =$B$4*$B$5^(A32-1) -> 19.868944 | D32: =$B$8*A32 -> 0.24 | E32: =MIN(상수!$B$10+$B$9*A32,상수!$B$12) -> 0.086 | F32: =1+E32*상수!$B$11 -> 1.043 | G32: =C32*$B$6*(1+D32)*F32*$B$7 -> 30.836284 | H32: =$B$15*B32 -> 104.3565 | I32: =H32/G32 -> 3.3842113 | J32: =INDEX(레벨표!$D:$D,MATCH(A32,레벨표!$A:$A,0))+$B$10*A32 -> 268 | K32: =$B$11*A32+$B$12 -> 164 | L32: =MIN(K32/(K32+상수!$B$4*A32+상수!$B$5),상수!$B$6) -> 0.41624365 | M32: =$B$16*INDEX(레벨표!$C:$C,MATCH(A32,레벨표!$A:$A,0))*(1-L32) -> 7.5317014 | N32: =J32/M32 -> 35.582929 | O32: =N32*$B$17 -> 53.374394 | P32: =$B$13 -> 2.5 | Q32: =$B$14 -> 15
... A70: 50 | B70: =INDEX(레벨표!$B:$B,MATCH(A70,레벨표!$A:$A,0)) -> 258.03767 | C70: =$B$4*$B$5^(A70-1) -> 1243.4255 | D70: =$B$8*A70 -> 1 | E70: =MIN(상수!$B$10+$B$9*A70,상수!$B$12) -> 0.2 | F70: =1+E70*상수!$B$11 -> 1.1 | G70: =C70*$B$6*(1+D70)*F70*$B$7 -> 3282.6432 | H70: =$B$15*B70 -> 7741.1301 | I70: =H70/G70 -> 2.3582003 | J70: =INDEX(레벨표!$D:$D,MATCH(A70,레벨표!$A:$A,0))+$B$10*A70 -> 800 | K70: =$B$11*A70+$B$12 -> 620 | L70: =MIN(K70/(K70+상수!$B$4*A70+상수!$B$5),상수!$B$6) -> 0.43661972 | M70: =$B$16*INDEX(레벨표!$C:$C,MATCH(A70,레벨표!$A:$A,0))*(1-L70) -> 192.16312 | N70: =J70/M70 -> 4.1631297 | O70: =N70*$B$17 -> 6.2446945 | P70: =$B$13 -> 2.5 | Q70: =$B$14 -> 15
